Workbook

Sheet Start Here
B2: Bella's Car Search
B3: Live CARFAX inventory - 2022+ Toyota / Honda / Subaru SUVs within 75 miles of Elkhart, IN
B4: Data pulled | C4: September 14, 2026 from CARFAX used-car listings
B5: Search area | C5: Elkhart, IN 46514 - 75 mile radius (South Bend, Mishawaka, Goshen, Warsaw, Fort Wayne, Kalamazoo, Niles)
B7: The Funnel
B8: Filter applied | C8: Cars remaining
B9: All 2022+ RAV4 / 4Runner / CR-V / HR-V / Outback under $40k in radius | C9: 262
B10: ...that are AWD or 4WD | C10: 234
B11: ...with no accidents reported | C11: 173
B12: ...with service history on file | C12: 168
B13: ...under your mileage cap (Toyota 100k / Honda 70k / Subaru 50k) | C13: 144
B14: ...rated GOOD or GREAT value by CARFAX | C14: 53
B15: ...with heated seats | C15: 36
B16: ...with Apple CarPlay (standard on all of these - no cars lost) | C16: 36
B17: ...that are also Certified Pre-Owned | C17: 6
B18: Certified Pre-Owned is scored as a strong bonus rather than a hard filter, so the Shortlist holds 36 cars and the 6 certified ones float near the top. To see only CPO, set "Require Certified Pre-Owned" to TRUE on the Search Criteria tab.
B20: The Tabs
B21: Shortlist | C21: The 36 cars that meet every one of your criteria, ranked best first. Start here.
B22: Top 10 Compare | C22: The ten best side by side - price, miles, history, features, dealer - for a quick head-to-head.
B23: All Cars | C23: All 262 listings with every data point. Use the filter arrows to explore or loosen a requirement.
B24: Search Criteria | C24: The yellow cells that drive the YES/no "Meets All" column. Change a cap and the whole sheet re-flags.
B25: Scoring Weights | C25: The yellow cells that drive the Score. Change a weight and every car instantly re-ranks.
B26: Model Benchmarks | C26: What each model-year actually sells for here, so you can tell a real deal from a normal price.
B28: How the Score Works
B29: Every car gets six sub-scores from 0 to 100, blended using the weights you set. The weighting follows the priority you gave: reliability first, then price, then mileage, then features.
B30: Component | C30: What it measures | D30: Weight
B31: Reliability & History | C31: CARFAX's model reliability rating, projected repair cost and risk (60%), blended with this specific car's history - accident-free, one owner, personal use, how many service records (40%). | D31: ='Scoring Weights'!B5/100 -> 0.26
B32: Price / Value | C32: The CARFAX Great/Good/Fair value badge (55%), blended with how far below the going rate it is priced (45%). The going rate is fitted from the 262 real listings in this sheet, adjusting for year and mileage. | D32: ='Scoring Weights'!B6/100 -> 0.22
B33: Mileage | C33: Miles against your cap for that make (70%), plus miles-per-year against a 12,000/yr normal (30%). | D33: ='Scoring Weights'!B7/100 -> 0.18
B34: Certified Pre-Owned | C34: 100 if factory certified, 0 if not. | D34: ='Scoring Weights'!B8/100 -> 0.15
B35: Features | C35: Heated steering, sunroof, blind spot, power liftgate, leather, remote start, navigation, wireless charging, parking sensors, power seat, premium audio. | D35: ='Scoring Weights'!B9/100 -> 0.14
B36: Distance | C36: 100 at your doorstep, 0 at 75 miles. Tiebreaker only. | D36: ='Scoring Weights'!B10/100 -> 0.05
B39: Live Counts
B40: Cars meeting every criterion | C40: =COUNTIF('All Cars'!$C$5:$C$266,"YES") -> 36
B41: Of those, Certified Pre-Owned | C41: =COUNTIFS('All Cars'!$C$5:$C$266,"YES",'All Cars'!$K$5:$K$266,"Yes") -> 6
B42: Total listings tracked | C42: =COUNTA('All Cars'!$BC$5:$BC$266) -> 262
B43: These recalculate from the Search Criteria tab, so you can see instantly how many cars survive a change before you go looking.
B45: Before You Buy - Read This
B46: Verify CPO with the dealer | C46: CARFAX flags certification from the dealer feed. Confirm it is manufacturer certified (Toyota TCUV, Honda HondaTrue, Subaru Certified) and not a dealer in-house warranty - the warranty difference is significant.
B47: Features come from the trim, not the VIN | C47: Heated seats, sunroof and the rest are read from the factory equipment list for that trim. It is accurate for standard equipment but can miss optional packages. Confirm on the window sticker.
...

Sheet Search Criteria
A1: Search Criteria
A2: Edit the yellow cells. Every YES/NO in the "Meets All" column recalculates from these.
A4: Filter | B4: Value | C4: Notes
A5: Max Price ($) | B5: 40000 | C5: Listing price, before tax/title/doc fee.
A6: Min Year | B6: 2022 | C6: Model year.
A7: Max Distance (mi) | B7: 75 | C7: Straight-line distance from Elkhart, IN 46514.
A8: Require AWD / 4WD | B8: =TRUE() -> TRUE | C8: TRUE or FALSE.
A9: Require No Accidents | B9: =TRUE() -> TRUE | C9: No accident or damage reported to CARFAX.
A10: Require Service History | B10: =TRUE() -> TRUE | C10: At least one service record on file.
A11: Require Heated Seats | B11: =TRUE() -> TRUE | C11: From the trim equipment list.
A12: Require Good/Great Value | B12: =TRUE() -> TRUE | C12: CARFAX's own value badge must be GOOD or GREAT.
A13: Require Certified Pre-Owned | B13: =FALSE() -> FALSE | C13: Set TRUE to see only CPO cars (that leaves 6).
A16: Mileage Cap by Make
A17: Make | B17: Max Miles | C17: Notes
A18: Toyota | B18: 100000 | C18: Your stated cap.
A19: Honda | B19: 70000 | C19: Your stated cap.
A20: Subaru | B20: 50000 | C20: Your stated cap.
A23: Models searched: Toyota 4Runner, Toyota RAV4, Honda HR-V, Honda CR-V, Subaru Outback.
A24: Apple CarPlay is standard on every 2022+ car in all five of these model lines, so it never eliminates anyone. It is shown as a column for confirmation.

Sheet Scoring Weights
A1: Scoring Weights
A2: Edit the yellow cells to re-rank every car instantly. They should add to 100.
A4: Component | B4: Weight | C4: What it measures
A5: Reliability & History | B5: 26 | C5: CARFAX model reliability rating, projected repair cost and risk (60%) blended with this car's own history - accident-free, one owner, personal use, number of service records (40%). Your #1 priority.
A6: Price / Value | B6: 22 | C6: CARFAX Great/Good/Fair value badge (55%) blended with how far the asking price sits below what a same-model car of that year and mileage typically lists for (45%). Your #2 priority.
A7: Mileage | B7: 18 | C7: Miles against your cap for that make (70%) blended with miles-per-year against a 12,000/yr normal (30%). Your #3 priority.
A8: Certified Pre-Owned | B8: 15 | C8: 100 if factory certified, 0 if not. Weighted heavily so CPO cars rise, without excluding good non-CPO cars.
A9: Features | B9: 14 | C9: Heated steering, sunroof, blind spot, power liftgate, leather, remote start, nav, wireless charging, parking sensors, power seat, premium audio. Your #4 priority.
A10: Distance | B10: 5 | C10: 100 at your doorstep down to 0 at 75 miles. Tiebreaker only.
A11: TOTAL | B11: =SUM(B5:B10) -> 100 | C11: =IF(B11=100,"OK - weights add to 100","ADJUST - weights must add to 100, currently "&B11) -> OK - weights add to 100

Sheet Shortlist
A1: Shortlist - 36 Cars That Meet Every Criterion
A2: AWD/4WD, no accidents, service history on file, under your mileage cap for the make, GOOD or GREAT value, heated seats, Apple CarPlay. Ranked best-value first. Certified cars are marked and scored higher.
A4: Rank | B4: Score | C4: Still Meets | D4: Year | E4: Make | F4: Model | G4: Trim | H4: Price | I4: Mileage | J4: Miles/Yr | K4: CPO | L4: Value Badge | M4: vs Market | N4: Reliability | O4: Owners | P4: Service Recs | Q4: Sunroof/Moonroof | R4: Leather | S4: Power Liftgate | T4: Blind Spot | U4: Fuel | V4: MPG | W4: Dealer | X4: City | Y4: Miles Away | Z4: Est. Monthly | AA4: CarFax Link | AB4: Listing URL
A5: =RANK(B5,$B$5:$B$40) -> 1 | B5: ='All Cars'!B5 -> 84 | C5: ='All Cars'!C5 -> YES | D5: ='All Cars'!D5 -> 2026 | E5: ='All Cars'!E5 -> Honda | F5: ='All Cars'!F5 -> CR-V | G5: ='All Cars'!G5 -> EXL | H5: ='All Cars'!H5 -> 35415 | I5: ='All Cars'!I5 -> 12036 | ... K5: ='All Cars'!K5 -> Yes | L5: ='All Cars'!O5 -> GREAT | M5: ='All Cars'!Q5 -> 0.026 | N5: ='All Cars'!R5 -> GREAT | O5: ='All Cars'!U5 -> 1 | P5: ='All Cars'!W5 -> 6 | Q5: ='All Cars'!AA5 -> Yes | R5: ='All Cars'!AD5 -> Yes | S5: ='All Cars'!AC5 -> Yes | T5: ='All Cars'!AB5 -> Yes | U5: ='All Cars'!M5 -> Gasoline | V5: ='All Cars'!N5 -> 29 | W5: ='All Cars'!AN5 -> Gurley Leep Honda | X5: ='All Cars'!AO5 -> Elkhart | Y5: ='All Cars'!AQ5 -> 0.4 | Z5: ='All Cars'!AU5 -> 632.64 | AA5: 2026 Honda CR-V EXL | AB5: https://www.carfax.com/vehicle/2HKRS4H73TH412625
A6: =RANK(B6,$B$5:$B$40) -> 2 | B6: ='All Cars'!B6 -> 72.4 | C6: ='All Cars'!C6 -> YES | D6: ='All Cars'!D6 -> 2025 | E6: ='All Cars'!E6 -> Honda | F6: ='All Cars'!F6 -> CR-V | G6: ='All Cars'!G6 -> EX | H6: ='All Cars'!H6 -> 32809 | I6: ='All Cars'!I6 -> 15682 | ... K6: ='All Cars'!K6 -> Yes | L6: ='All Cars'!O6 -> GREAT | M6: ='All Cars'!Q6 -> 0.062 | N6: ='All Cars'!R6 -> GREAT | O6: ='All Cars'!U6 -> 1 | P6: ='All Cars'!W6 -> 4 | Q6: ='All Cars'!AA6 -> Yes | R6: ='All Cars'!AD6 -> No | S6: ='All Cars'!AC6 -> No | T6: ='All Cars'!AB6 -> Yes | U6: ='All Cars'!M6 -> Gasoline | V6: ='All Cars'!N6 -> 28 | W6: ='All Cars'!AN6 -> Crown Motors Cadillac Buick Honda Mazda | X6: ='All Cars'!AO6 -> Holland | Y6: ='All Cars'!AQ6 -> 71 | Z6: ='All Cars'!AU6 -> 586.09 | AA6: 2025 Honda CR-V EX | AB6: https://www.carfax.com/vehicle/5J6RS4H46SL018336
A7: =RANK(B7,$B$5:$B$40) -> 3 | B7: ='All Cars'!B9 -> 70 | C7: ='All Cars'!C9 -> YES | D7: ='All Cars'!D9 -> 2025 | E7: ='All Cars'!E9 -> Subaru | F7: ='All Cars'!F9 -> Outback | G7: ='All Cars'!G9 -> Limited | H7: ='All Cars'!H9 -> 32609 | I7: ='All Cars'!I9 -> 31763 | ... K7: ='All Cars'!K9 -> Yes | L7: ='All Cars'!O9 -> GOOD | M7: ='All Cars'!Q9 -> -0.051 | N7: ='All Cars'!R9 -> GREAT | O7: ='All Cars'!U9 -> 1 | P7: ='All Cars'!W9 -> 6 | Q7: ='All Cars'!AA9 -> Yes | R7: ='All Cars'!AD9 -> Yes | S7: ='All Cars'!AC9 -> Yes | T7: ='All Cars'!AB9 -> Yes | U7: ='All Cars'!M9 -> Gasoline | V7: ='All Cars'!N9 -> 28 | W7: ='All Cars'!AN9 -> Fox Maple Hill | X7: ='All Cars'!AO9 -> Kalamazoo | Y7: ='All Cars'!AQ9 -> 42.8 | Z7: ='All Cars'!AU9 -> 582.51 | AA7: 2025 Subaru Outback Limited | AB7: https://www.carfax.com/vehicle/4S4BTANC7S3132470
A8: =RANK(B8,$B$5:$B$40) -> 4 | B8: ='All Cars'!B12 -> 69 | C8: ='All Cars'!C12 -> YES | D8: ='All Cars'!D12 -> 2024 | E8: ='All Cars'!E12 -> Honda | F8: ='All Cars'!F12 -> CR-V | G8: ='All Cars'!G12 -> Sport | H8: ='All Cars'!H12 -> 33809 | I8: ='All Cars'!I12 -> 25381 | ... K8: ='All Cars'!K12 -> Yes | L8: ='All Cars'!O12 -> GOOD | M8: ='All Cars'!Q12 -> -0.02 | N8: ='All Cars'!R12 -> GREAT | O8: ='All Cars'!U12 -> 1 | P8: ='All Cars'!W12 -> 6 | Q8: ='All Cars'!AA12 -> Yes | R8: ='All Cars'!AD12 -> Yes | S8: ='All Cars'!AC12 -> No | T8: ='All Cars'!AB12 -> Yes | U8: ='All Cars'!M12 -> Hybrid | V8: ='All Cars'!N12 -> 37 | W8: ='All Cars'!AN12 -> Crown Motors Cadillac Buick Honda Mazda | X8: ='All Cars'!AO12 -> Holland | Y8: ='All Cars'!AQ12 -> 71 | Z8: ='All Cars'!AU12 -> 603.95 | AA8: 2024 Honda CR-V Sport | AB8: https://www.carfax.com/vehicle/7FARS6H5XRE073206
A9: =RANK(B9,$B$5:$B$40) -> 5 | B9: ='All Cars'!B13 -> 68.1 | C9: ='All Cars'!C13 -> YES | D9: ='All Cars'!D13 -> 2026 | E9: ='All Cars'!E13 -> Honda | F9: ='All Cars'!F13 -> CR-V | G9: ='All Cars'!G13 -> TrailSport | H9: ='All Cars'!H13 -> 35913 | I9: ='All Cars'!I13 -> 9420 | ... K9: ='All Cars'!K13 -> No | L9: ='All Cars'!O13 -> GREAT | M9: ='All Cars'!Q13 -> 0.017 | N9: ='All Cars'!R13 -> n/a | O9: ='All Cars'!U13 -> 1 | P9: ='All Cars'!W13 -> 3 | Q9: ='All Cars'!AA13 -> Yes | R9: ='All Cars'!AD13 -> Yes | S9: ='All Cars'!AC13 -> Yes | T9: ='All Cars'!AB13 -> Yes | U9: ='All Cars'!M13 -> Hybrid | V9: ='All Cars'!N13 -> 35 | W9: ='All Cars'!AN13 -> Gurley Leep Kia | X9: ='All Cars'!AO13 -> Mishawaka | Y9: ='All Cars'!AQ13 -> 11 | Z9: ='All Cars'!AU13 -> 641.53 | AA9: 2026 Honda CR-V TrailSport | AB9: https://www.carfax.com/vehicle/7FARS6H69TE031075
A10: =RANK(B10,$B$5:$B$40) -> 6 | B10: ='All Cars'!B17 -> 66.6 | C10: ='All Cars'!C17 -> YES | D10: ='All Cars'!D17 -> 2023 | E10: ='All Cars'!E17 -> Honda | F10: ='All Cars'!F17 -> CR-V | G10: ='All Cars'!G17 -> Sport Touring | H10: ='All Cars'!H17 -> 32864 | I10: ='All Cars'!I17 -> 34991 | ... K10: ='All Cars'!K17 -> No | L10: ='All Cars'!O17 -> GREAT | M10: ='All Cars'!Q17 -> -0.048 | N10: ='All Cars'!R17 -> n/a | O10: ='All Cars'!U17 -> 2 | P10: ='All Cars'!W17 -> 10 | Q10: ='All Cars'!AA17 -> Yes | R10: ='All Cars'!AD17 -> Yes | S10: ='All Cars'!AC17 -> Yes | T10: ='All Cars'!AB17 -> Yes | U10: ='All Cars'!M17 -> Hybrid | V10: ='All Cars'!N17 -> 37 | W10: ='All Cars'!AN17 -> Gurley Leep Hyundai Subaru | X10: ='All Cars'!AO17 -> Mishawaka | Y10: ='All Cars'!AQ17 -> 10.8 | Z10: ='All Cars'!AU17 -> 587.07 | AA10: 2023 Honda CR-V Sport Touring | AB10: https://www.carfax.com/vehicle/5J6RS6H93PL004196
A11: =RANK(B11,$B$5:$B$40) -> 7 | B11: ='All Cars'!B18 -> 66.5 | C11: ='All Cars'!C18 -> YES | D11: ='All Cars'!D18 -> 2025 | E11: ='All Cars'!E18 -> Honda | F11: ='All Cars'!F18 -> CR-V | G11: ='All Cars'!G18 -> EX | H11: ='All Cars'!H18 -> 32809 | I11: ='All Cars'!I18 -> 23351 | ... K11: ='All Cars'!K18 -> Yes | L11: ='All Cars'!O18 -> GOOD | M11: ='All Cars'!Q18 -> 0.047 | N11: ='All Cars'!R18 -> GREAT | O11: ='All Cars'!U18 -> 1 | P11: ='All Cars'!W18 -> 3 | Q11: ='All Cars'!AA18 -> Yes | R11: ='All Cars'!AD18 -> No | S11: ='All Cars'!AC18 -> No | T11: ='All Cars'!AB18 -> Yes | U11: ='All Cars'!M18 -> Gasoline | V11: ='All Cars'!N18 -> 28 | W11: ='All Cars'!AN18 -> Crown Motors Cadillac Buick Honda Mazda | X11: ='All Cars'!AO18 -> Holland | Y11: ='All Cars'!AQ18 -> 71 | Z11: ='All Cars'!AU18 -> 586.09 | AA11: 2025 Honda CR-V EX | AB11: https://www.carfax.com/vehicle/7FARS4H4XSE002962
A12: =RANK(B12,$B$5:$B$40) -> 8 | B12: ='All Cars'!B19 -> 66.1 | C12: ='All Cars'!C19 -> YES | D12: ='All Cars'!D19 -> 2025 | E12: ='All Cars'!E19 -> Honda | F12: ='All Cars'!F19 -> CR-V | G12: ='All Cars'!G19 -> Sport-L | H12: ='All Cars'!H19 -> 34798 | I12: ='All Cars'!I19 -> 20222 | ... K12: ='All Cars'!K19 -> No | L12: ='All Cars'!O19 -> GREAT | M12: ='All Cars'!Q19 -> -0.004 | N12: ='All Cars'!R19 -> n/a | O12: ='All Cars'!U19 -> 1 | P12: ='All Cars'!W19 -> 7 | Q12: ='All Cars'!AA19 -> Yes | R12: ='All Cars'!AD19 -> Yes | S12: ='All Cars'!AC19 -> Yes | T12: ='All Cars'!AB19 -> Yes | U12: ='All Cars'!M19 -> Hybrid | V12: ='All Cars'!N19 -> 37 | W12: ='All Cars'!AN19 -> Jordan Lexus of Mishawaka | X12: ='All Cars'!AO19 -> Mishawaka | Y12: ='All Cars'!AQ19 -> 11.1 | Z12: ='All Cars'!AU19 -> 621.62 | AA12: 2025 Honda CR-V Sport-L | AB12: https://www.carfax.com/vehicle/7FARS6H82SE006423
A13: =RANK(B13,$B$5:$B$40) -> 9 | B13: ='All Cars'!B22 -> 64.6 | C13: ='All Cars'!C22 -> YES | D13: ='All Cars'!D22 -> 2024 | E13: ='All Cars'!E22 -> Toyota | F13: ='All Cars'!F22 -> RAV4 | G13: ='All Cars'!G22 -> Limited Edition | H13: ='All Cars'!H22 -> 39338 | I13: ='All Cars'!I22 -> 17459 | ... K13: ='All Cars'!K22 -> No | L13: ='All Cars'!O22 -> GOOD | M13: ='All Cars'!Q22 -> -0.137 | N13: ='All Cars'!R22 -> n/a | O13: ='All Cars'!U22 -> 1 | P13: ='All Cars'!W22 -> 5 | Q13: ='All Cars'!AA22 -> Yes | R13: ='All Cars'!AD22 -> Yes | S13: ='All Cars'!AC22 -> Yes | T13: ='All Cars'!AB22 -> Yes | U13: ='All Cars'!M22 -> Gasoline | V13: ='All Cars'!N22 -> 28 | W13: ='All Cars'!AN22 -> Gurley Leep Buick GMC Cadillac | X13: ='All Cars'!AO22 -> Mishawaka | Y13: ='All Cars'!AQ22 -> 10.7 | Z13: ='All Cars'!AU22 -> 702.72 | AA13: 2024 Toyota RAV4 Limited Edition | AB13: https://www.carfax.com/vehicle/2T3N1RFV3RW451961
A14: =RANK(B14,$B$5:$B$40) -> 10 | B14: ='All Cars'!B23 -> 64.5 | C14: ='All Cars'!C23 -> YES | D14: ='All Cars'!D23 -> 2024 | E14: ='All Cars'!E23 -> Honda | F14: ='All Cars'!F23 -> CR-V | G14: ='All Cars'!G23 -> Sport-L | H14: ='All Cars'!H23 -> 35190 | I14: ='All Cars'!I23 -> 23100 | ... K14: ='All Cars'!K23 -> No | L14: ='All Cars'!O23 -> GREAT | M14: ='All Cars'!Q23 -> -0.056 | N14: ='All Cars'!R23 -> n/a | O14: ='All Cars'!U23 -> 2 | P14: ='All Cars'!W23 -> 10 | Q14: ='All Cars'!AA23 -> Yes | R14: ='All Cars'!AD23 -> Yes | S14: ='All Cars'!AC23 -> Yes | T14: ='All Cars'!AB23 -> Yes | U14: ='All Cars'!M23 -> Hybrid | V14: ='All Cars'!N23 -> 37 | W14: ='All Cars'!AN23 -> Zeigler Ford Lincoln Elkhart | X14: ='All Cars'!AO23 -> Elkhart | Y14: ='All Cars'!AQ23 -> 3.1 | Z14: ='All Cars'!AU23 -> 628.62 | AA14: 2024 Honda CR-V Sport-L | AB14: https://www.carfax.com/vehicle/7FARS6H8XRE020161
A15: =RANK(B15,$B$5:$B$40) -> 11 | B15: ='All Cars'!B24 -> 63.9 | C15: ='All Cars'!C24 -> YES | D15: ='All Cars'!D24 -> 2023 | E15: ='All Cars'!E24 -> Honda | F15: ='All Cars'!F24 -> CR-V | G15: ='All Cars'!G24 -> EXL | H15: ='All Cars'!H24 -> 32149 | I15: ='All Cars'!I24 -> 29404 | ... K15: ='All Cars'!K24 -> No | L15: ='All Cars'!O24 -> GOOD | M15: ='All Cars'!Q24 -> -0.013 | N15: ='All Cars'!R24 -> GREAT | O15: ='All Cars'!U24 -> 2 | P15: ='All Cars'!W24 -> 13 | Q15: ='All Cars'!AA24 -> Yes | R15: ='All Cars'!AD24 -> Yes | S15: ='All Cars'!AC24 -> Yes | T15: ='All Cars'!AB24 -> Yes | U15: ='All Cars'!M24 -> Gasoline | V15: ='All Cars'!N24 -> 29 | W15: ='All Cars'!AN24 -> Jordan Ford | X15: ='All Cars'!AO24 -> Mishawaka | Y15: ='All Cars'!AQ24 -> 10.7 | Z15: ='All Cars'!AU24 -> 574.3 | AA15: 2023 Honda CR-V EXL | AB15: https://www.carfax.com/vehicle/5J6RS4H76PL000890
A16: =RANK(B16,$B$5:$B$40) -> 12 | B16: ='All Cars'!B27 -> 63.7 | C16: ='All Cars'!C27 -> YES | D16: ='All Cars'!D27 -> 2024 | E16: ='All Cars'!E27 -> Honda | F16: ='All Cars'!F27 -> CR-V | G16: ='All Cars'!G27 -> Sport Touring | H16: ='All Cars'!H27 -> 35270 | I16: ='All Cars'!I27 -> 34486 | ... K16: ='All Cars'!K27 -> No | L16: ='All Cars'!O27 -> GREAT | M16: ='All Cars'!Q27 -> -0.084 | N16: ='All Cars'!R27 -> n/a | O16: ='All Cars'!U27 -> 1 | P16: ='All Cars'!W27 -> 10 | Q16: ='All Cars'!AA27 -> Yes | R16: ='All Cars'!AD27 -> Yes | S16: ='All Cars'!AC27 -> Yes | T16: ='All Cars'!AB27 -> Yes | U16: ='All Cars'!M27 -> Hybrid | V16: ='All Cars'!N27 -> 37 | W16: ='All Cars'!AN27 -> Signature Toyota Hyundai | X16: ='All Cars'!AO27 -> Benton Harbor | Y16: ='All Cars'!AQ27 -> 34.7 | Z16: ='All Cars'!AU27 -> 630.05 | AA16: 2024 Honda CR-V Sport Touring | AB16: https://www.carfax.com/vehicle/7FARS6H92RE014122
A17: =RANK(B17,$B$5:$B$40) -> 13 | B17: ='All Cars'!B29 -> 63.2 | C17: ='All Cars'!C29 -> YES | D17: ='All Cars'!D29 -> 2024 | E17: ='All Cars'!E29 -> Honda | F17: ='All Cars'!F29 -> CR-V | G17: ='All Cars'!G29 -> Sport-L | H17: ='All Cars'!H29 -> 34185 | I17: ='All Cars'!I29 -> 34150 | ... K17: ='All Cars'!K29 -> No | L17: ='All Cars'!O29 -> GREAT | M17: ='All Cars'!Q29 -> -0.05 | N17: ='All Cars'!R29 -> n/a | O17: ='All Cars'!U29 -> 1 | P17: ='All Cars'!W29 -> 7 | Q17: ='All Cars'!AA29 -> Yes | R17: ='All Cars'!AD29 -> Yes | S17: ='All Cars'!AC29 -> Yes | T17: ='All Cars'!AB29 -> Yes | U17: ='All Cars'!M29 -> Hybrid | V17: ='All Cars'!N29 -> 37 | W17: ='All Cars'!AN29 -> Gurley Leep Honda | X17: ='All Cars'!AO29 -> Elkhart | Y17: ='All Cars'!AQ29 -> 0.4 | Z17: ='All Cars'!AU29 -> 610.67 | AA17: 2024 Honda CR-V Sport-L | AB17: https://www.carfax.com/vehicle/7FARS6H84RE043984
A18: =RANK(B18,$B$5:$B$40) -> 14 | B18: ='All Cars'!B32 -> 62.9 | C18: ='All Cars'!C32 -> YES | D18: ='All Cars'!D32 -> 2025 | E18: ='All Cars'!E32 -> Toyota | F18: ='All Cars'!F32 -> RAV4 | G18: ='All Cars'!G32 -> XLE | H18: ='All Cars'!H32 -> 36252 | I18: ='All Cars'!I32 -> 14982 | ... K18: ='All Cars'!K32 -> No | L18: ='All Cars'!O32 -> GREAT | M18: ='All Cars'!Q32 -> -0.008 | N18: ='All Cars'!R32 -> GREAT | O18: ='All Cars'!U32 -> 1 | P18: ='All Cars'!W32 -> 4 | Q18: ='All Cars'!AA32 -> Yes | R18: ='All Cars'!AD32 -> No | S18: ='All Cars'!AC32 -> No | T18: ='All Cars'!AB32 -> Yes | U18: ='All Cars'!M32 -> Hybrid | V18: ='All Cars'!N32 -> 39 | W18: ='All Cars'!AN32 -> Michiana Chrysler Dodge Jeep Ram Fiat | X18: ='All Cars'!AO32 -> Mishawaka | Y18: ='All Cars'!AQ32 -> 11 | Z18: ='All Cars'!AU32 -> 647.59 | AA18: 2025 Toyota RAV4 XLE | AB18: https://www.carfax.com/vehicle/4T3RWRFV4SU211732
A19: =RANK(B19,$B$5:$B$40) -> 15 | B19: ='All Cars'!B33 -> 62.7 | C19: ='All Cars'!C33 -> YES | D19: ='All Cars'!D33 -> 2025 | E19: ='All Cars'!E33 -> Toyota | F19: ='All Cars'!F33 -> RAV4 | G19: ='All Cars'!G33 -> XLE | H19: ='All Cars'!H33 -> 35719 | I19: ='All Cars'!I33 -> 54139 | ... K19: ='All Cars'!K33 -> Yes | L19: ='All Cars'!O33 -> GOOD | M19: ='All Cars'!Q33 -> -0.087 | N19: ='All Cars'!R33 -> GREAT | O19: ='All Cars'!U33 -> 1 | P19: ='All Cars'!W33 -> 6 | Q19: ='All Cars'!AA33 -> Yes | R19: ='All Cars'!AD33 -> No | S19: ='All Cars'!AC33 -> No | T19: ='All Cars'!AB33 -> Yes | U19: ='All Cars'!M33 -> Hybrid | V19: ='All Cars'!N33 -> 39 | W19: ='All Cars'!AN33 -> Crown Toyota Volkswagen | X19: ='All Cars'!AO33 -> Holland | Y19: ='All Cars'!AQ33 -> 74.7 | Z19: ='All Cars'!AU33 -> 638.07 | AA19: 2025 Toyota RAV4 XLE | AB19: https://www.carfax.com/vehicle/JTMRWRFV5SD591595
A20: =RANK(B20,$B$5:$B$40) -> 16 | B20: ='All Cars'!B35 -> 62.1 | C20: ='All Cars'!C35 -> YES | D20: ='All Cars'!D35 -> 2025 | E20: ='All Cars'!E35 -> Subaru | F20: ='All Cars'!F35 -> Outback | G20: ='All Cars'!G35 -> Onyx Edition | H20: ='All Cars'!H35 -> 31233 | I20: ='All Cars'!I35 -> 16159 | ... K20: ='All Cars'!K35 -> No | L20: ='All Cars'!O35 -> GREAT | M20: ='All Cars'!Q35 -> 0.045 | N20: ='All Cars'!R35 -> GOOD | O20: ='All Cars'!U35 -> 1 | P20: ='All Cars'!W35 -> 6 | Q20: ='All Cars'!AA35 -> Yes | R20: ='All Cars'!AD35 -> Yes | S20: ='All Cars'!AC35 -> Yes | T20: ='All Cars'!AB35 -> Yes | U20: ='All Cars'!M35 -> Gasoline | V20: ='All Cars'!N35 -> 28 | W20: ='All Cars'!AN35 -> Toyota of Warsaw | X20: ='All Cars'!AO35 -> Warsaw | Y20: ='All Cars'!AQ35 -> 31.9 | Z20: ='All Cars'!AU35 -> 557.93 | AA20: 2025 Subaru Outback Onyx Edition | AB20: https://www.carfax.com/vehicle/4S4BTALC4S3182780
A21: =RANK(B21,$B$5:$B$40) -> 17 | B21: ='All Cars'!B41 -> 61.1 | C21: ='All Cars'!C41 -> YES | D21: ='All Cars'!D41 -> 2025 | E21: ='All Cars'!E41 -> Honda | F21: ='All Cars'!F41 -> CR-V | G21: ='All Cars'!G41 -> Sport-L | H21: ='All Cars'!H41 -> 35094 | I21: ='All Cars'!I41 -> 29734 | ... K21: ='All Cars'!K41 -> No | L21: ='All Cars'!O41 -> GREAT | M21: ='All Cars'!Q41 -> -0.032 | N21: ='All Cars'!R41 -> n/a | O21: ='All Cars'!U41 -> 2 | P21: ='All Cars'!W41 -> 9 | Q21: ='All Cars'!AA41 -> Yes | R21: ='All Cars'!AD41 -> Yes | S21: ='All Cars'!AC41 -> Yes | T21: ='All Cars'!AB41 -> Yes | U21: ='All Cars'!M41 -> Hybrid | V21: ='All Cars'!N41 -> 37 | W21: ='All Cars'!AN41 -> Gurley Leep Honda | X21: ='All Cars'!AO41 -> Elkhart | Y21: ='All Cars'!AQ41 -> 0.4 | Z21: ='All Cars'!AU41 -> 626.9 | AA21: 2025 Honda CR-V Sport-L | AB21: https://www.carfax.com/vehicle/7FARS6H88SE008967
A22: =RANK(B22,$B$5:$B$40) -> 18 | B22: ='All Cars'!B45 -> 59.4 | C22: ='All Cars'!C45 -> YES | D22: ='All Cars'!D45 -> 2025 | E22: ='All Cars'!E45 -> Subaru | F22: ='All Cars'!F45 -> Outback | G22: ='All Cars'!G45 -> Onyx Edition | H22: ='All Cars'!H45 -> 28149 | I22: ='All Cars'!I45 -> 33731 | ... K22: ='All Cars'!K45 -> No | L22: ='All Cars'!O45 -> GOOD | M22: ='All Cars'!Q45 -> 0.087 | N22: ='All Cars'!R45 -> GREAT | O22: ='All Cars'!U45 -> 1 | P22: ='All Cars'!W45 -> 4 | Q22: ='All Cars'!AA45 -> Yes | R22: ='All Cars'!AD45 -> Yes | S22: ='All Cars'!AC45 -> Yes | T22: ='All Cars'!AB45 -> Yes | U22: ='All Cars'!M45 -> Gasoline | V22: ='All Cars'!N45 -> 28 | W22: ='All Cars'!AN45 -> Gurley Leep Honda | X22: ='All Cars'!AO45 -> Elkhart | Y22: ='All Cars'!AQ45 -> 0.4 | Z22: ='All Cars'!AU45 -> 502.84 | AA22: 2025 Subaru Outback Onyx Edition | AB22: https://www.carfax.com/vehicle/4S4BTALC3S3187209
A23: =RANK(B23,$B$5:$B$40) -> 19 | B23: ='All Cars'!B46 -> 59.2 | C23: ='All Cars'!C46 -> YES | D23: ='All Cars'!D46 -> 2025 | E23: ='All Cars'!E46 -> Toyota | F23: ='All Cars'!F46 -> RAV4 | G23: ='All Cars'!G46 -> XLE Premium | H23: ='All Cars'!H46 -> 39185 | I23: ='All Cars'!I46 -> 15206 | ... K23: ='All Cars'!K46 -> No | L23: ='All Cars'!O46 -> GOOD | M23: ='All Cars'!Q46 -> -0.09 | N23: ='All Cars'!R46 -> GREAT | O23: ='All Cars'!U46 -> 1 | P23: ='All Cars'!W46 -> 5 | Q23: ='All Cars'!AA46 -> Yes | R23: ='All Cars'!AD46 -> Yes | S23: ='All Cars'!AC46 -> Yes | T23: ='All Cars'!AB46 -> Yes | U23: ='All Cars'!M46 -> Gasoline | V23: ='All Cars'!N46 -> 28 | W23: ='All Cars'!AN46 -> Bob Thomas Ford West | X23: ='All Cars'!AO46 -> Fort Wayne | Y23: ='All Cars'!AQ46 -> 59.9 | Z23: ='All Cars'!AU46 -> 699.98 | AA23: 2025 Toyota RAV4 XLE Premium | AB23: https://www.carfax.com/vehicle/2T3A1RFV1SW502278
A24: =RANK(B24,$B$5:$B$40) -> 20 | B24: ='All Cars'!B48 -> 59 | C24: ='All Cars'!C48 -> YES | D24: ='All Cars'!D48 -> 2024 | E24: ='All Cars'!E48 -> Honda | F24: ='All Cars'!F48 -> CR-V | G24: ='All Cars'!G48 -> Sport | H24: ='All Cars'!H48 -> 33249 | I24: ='All Cars'!I48 -> 31775 | ... K24: ='All Cars'!K48 -> No | L24: ='All Cars'!O48 -> GREAT | M24: ='All Cars'!Q48 -> -0.016 | N24: ='All Cars'!R48 -> n/a | O24: ='All Cars'!U48 -> 2 | P24: ='All Cars'!W48 -> 8 | Q24: ='All Cars'!AA48 -> Yes | R24: ='All Cars'!AD48 -> Yes | S24: ='All Cars'!AC48 -> No | T24: ='All Cars'!AB48 -> Yes | U24: ='All Cars'!M48 -> Hybrid | V24: ='All Cars'!N48 -> 37 | W24: ='All Cars'!AN48 -> Jordan Ford | X24: ='All Cars'!AO48 -> Mishawaka | Y24: ='All Cars'!AQ48 -> 10.7 | Z24: ='All Cars'!AU48 -> 593.95 | AA24: 2024 Honda CR-V Sport | AB24: https://www.carfax.com/vehicle/7FARS6H56RE044785
A25: =RANK(B25,$B$5:$B$40) -> 21 | B25: ='All Cars'!B50 -> 58.6 | C25: ='All Cars'!C50 -> YES | D25: ='All Cars'!D50 -> 2025 | E25: ='All Cars'!E50 -> Honda | F25: ='All Cars'!F50 -> CR-V | G25: ='All Cars'!G50 -> Sport-L | H25: ='All Cars'!H50 -> 36597 | I25: ='All Cars'!I50 -> 16535 | ... K25: ='All Cars'!K50 -> No | L25: ='All Cars'!O50 -> GOOD | M25: ='All Cars'!Q50 -> -0.049 | N25: ='All Cars'!R50 -> GREAT | O25: ='All Cars'!U50 -> 2 | P25: ='All Cars'!W50 -> 5 | Q25: ='All Cars'!AA50 -> Yes | R25: ='All Cars'!AD50 -> Yes | S25: ='All Cars'!AC50 -> Yes | T25: ='All Cars'!AB50 -> Yes | U25: ='All Cars'!M50 -> Hybrid | V25: ='All Cars'!N50 -> 37 | W25: ='All Cars'!AN50 -> Gurley Leep Honda | X25: ='All Cars'!AO50 -> Elkhart | Y25: ='All Cars'!AQ50 -> 0.4 | Z25: ='All Cars'!AU50 -> 653.75 | AA25: 2025 Honda CR-V Sport-L | AB25: https://www.carfax.com/vehicle/7FARS6H89SE024319
A26: =RANK(B26,$B$5:$B$40) -> 22 | B26: ='All Cars'!B53 -> 57.9 | C26: ='All Cars'!C53 -> YES | D26: ='All Cars'!D53 -> 2024 | E26: ='All Cars'!E53 -> Subaru | F26: ='All Cars'!F53 -> Outback | G26: ='All Cars'!G53 -> Limited XT | H26: ='All Cars'!H53 -> 30238 | I26: ='All Cars'!I53 -> 25726 | ... K26: ='All Cars'!K53 -> No | L26: ='All Cars'!O53 -> GOOD | M26: ='All Cars'!Q53 -> -0.008 | N26: ='All Cars'!R53 -> GOOD | O26: ='All Cars'!U53 -> 1 | P26: ='All Cars'!W53 -> 9 | Q26: ='All Cars'!AA53 -> Yes | R26: ='All Cars'!AD53 -> Yes | S26: ='All Cars'!AC53 -> Yes | T26: ='All Cars'!AB53 -> Yes | U26: ='All Cars'!M53 -> Gasoline | V26: ='All Cars'!N53 -> 25 | W26: ='All Cars'!AN53 -> Victory Honda Michigan City | X26: ='All Cars'!AO53 -> MICHIGAN CITY | Y26: ='All Cars'!AQ53 -> 46.9 | Z26: ='All Cars'!AU53 -> 540.16 | AA26: 2024 Subaru Outback Limited XT | AB26: https://www.carfax.com/vehicle/4S4BTGND3R3143827
A27: =RANK(B27,$B$5:$B$40) -> 23 | B27: ='All Cars'!B55 -> 57.7 | C27: ='All Cars'!C55 -> YES | D27: ='All Cars'!D55 -> 2022 | E27: ='All Cars'!E55 -> Honda | F27: ='All Cars'!F55 -> CR-V | G27: ='All Cars'!G55 -> EXL | H27: ='All Cars'!H55 -> 27793 | I27: ='All Cars'!I55 -> 49644 | ... K27: ='All Cars'!K55 -> No | L27: ='All Cars'!O55 -> GREAT | M27: ='All Cars'!Q55 -> 0.048 | N27: ='All Cars'!R55 -> GREAT | O27: ='All Cars'!U55 -> 3 | P27: ='All Cars'!W55 -> 12 | Q27: ='All Cars'!AA55 -> Yes | R27: ='All Cars'!AD55 -> Yes | S27: ='All Cars'!AC55 -> Yes | T27: ='All Cars'!AB55 -> Yes | U27: ='All Cars'!M55 -> Gasoline | V27: ='All Cars'!N55 -> 29 | W27: ='All Cars'!AN55 -> Jim Stykemain Ford | X27: ='All Cars'!AO55 -> Garrett | Y27: ='All Cars'!AQ55 -> 50.6 | Z27: ='All Cars'!AU55 -> 496.48 | AA27: 2022 Honda CR-V EXL | AB27: https://www.carfax.com/vehicle/5J6RW2H87NA000701
A28: =RANK(B28,$B$5:$B$40) -> 24 | B28: ='All Cars'!B57 -> 57.4 | C28: ='All Cars'!C57 -> YES | D28: ='All Cars'!D57 -> 2025 | E28: ='All Cars'!E57 -> Honda | F28: ='All Cars'!F57 -> CR-V | G28: ='All Cars'!G57 -> Sport-L | H28: ='All Cars'!H57 -> 35897 | I28: ='All Cars'!I57 -> 27590 | ... K28: ='All Cars'!K57 -> No | L28: ='All Cars'!O57 -> GOOD | M28: ='All Cars'!Q57 -> -0.052 | N28: ='All Cars'!R57 -> GREAT | O28: ='All Cars'!U57 -> 2 | P28: ='All Cars'!W57 -> 12 | Q28: ='All Cars'!AA57 -> Yes | R28: ='All Cars'!AD57 -> Yes | S28: ='All Cars'!AC57 -> Yes | T28: ='All Cars'!AB57 -> Yes | U28: ='All Cars'!M57 -> Hybrid | V28: ='All Cars'!N57 -> 37 | W28: ='All Cars'!AN57 -> Gurley Leep Honda | X28: ='All Cars'!AO57 -> Elkhart | Y28: ='All Cars'!AQ57 -> 0.4 | Z28: ='All Cars'!AU57 -> 641.25 | AA28: 2025 Honda CR-V Sport-L | AB28: https://www.carfax.com/vehicle/7FARS6H86SE022138
A29: =RANK(B29,$B$5:$B$40) -> 25 | B29: ='All Cars'!B58 -> 57.3 | C29: ='All Cars'!C58 -> YES | D29: ='All Cars'!D58 -> 2025 | E29: ='All Cars'!E58 -> Honda | F29: ='All Cars'!F58 -> HR-V | G29: ='All Cars'!G58 -> Sport | H29: ='All Cars'!H58 -> 27095 | I29: ='All Cars'!I58 -> 21310 | ... K29: ='All Cars'!K58 -> No | L29: ='All Cars'!O58 -> GOOD | M29: ='All Cars'!Q58 -> 0.001 | N29: ='All Cars'!R58 -> GREAT | O29: ='All Cars'!U58 -> 1 | P29: ='All Cars'!W58 -> 5 | Q29: ='All Cars'!AA58 -> No | R29: ='All Cars'!AD58 -> Yes | S29: ='All Cars'!AC58 -> No | T29: ='All Cars'!AB58 -> Yes | U29: ='All Cars'!M58 -> Gasoline | V29: ='All Cars'!N58 -> 27 | W29: ='All Cars'!AN58 -> Gurley Leep Honda | X29: ='All Cars'!AO58 -> Elkhart | Y29: ='All Cars'!AQ58 -> 0.4 | Z29: ='All Cars'!AU58 -> 484.01 | AA29: 2025 Honda HR-V Sport | AB29: https://www.carfax.com/vehicle/3CZRZ2H51SM757265
A30: =RANK(B30,$B$5:$B$40) -> 26 | B30: ='All Cars'!B62 -> 56.8 | C30: ='All Cars'!C62 -> YES | D30: ='All Cars'!D62 -> 2025 | E30: ='All Cars'!E62 -> Toyota | F30: ='All Cars'!F62 -> RAV4 | G30: ='All Cars'!G62 -> XLE | H30: ='All Cars'!H62 -> 36395 | I30: ='All Cars'!I62 -> 11639 | ... K30: ='All Cars'!K62 -> No | L30: ='All Cars'!O62 -> GOOD | M30: ='All Cars'!Q62 -> -0.004 | N30: ='All Cars'!R62 -> GREAT | O30: ='All Cars'!U62 -> 2 | P30: ='All Cars'!W62 -> 3 | Q30: ='All Cars'!AA62 -> Yes | R30: ='All Cars'!AD62 -> No | S30: ='All Cars'!AC62 -> Yes | T30: ='All Cars'!AB62 -> Yes | U30: ='All Cars'!M62 -> Gasoline | V30: ='All Cars'!N62 -> 28 | W30: ='All Cars'!AN62 -> Sunshine Toyota | X30: ='All Cars'!AO62 -> Springfield | Y30: ='All Cars'!AQ62 -> 56.8 | Z30: ='All Cars'!AU62 -> 650.14 | AA30: 2025 Toyota RAV4 XLE | AB30: https://www.carfax.com/vehicle/2T3P1RFV7SC536558
A31: =RANK(B31,$B$5:$B$40) -> 27 | B31: ='All Cars'!B64 -> 56.6 | C31: ='All Cars'!C64 -> YES | D31: ='All Cars'!D64 -> 2023 | E31: ='All Cars'!E64 -> Honda | F31: ='All Cars'!F64 -> CR-V | G31: ='All Cars'!G64 -> EX | H31: ='All Cars'!H64 -> 29982 | I31: ='All Cars'!I64 -> 34721 | ... K31: ='All Cars'!K64 -> No | L31: ='All Cars'!O64 -> GOOD | M31: ='All Cars'!Q64 -> 0.044 | N31: ='All Cars'!R64 -> GREAT | O31: ='All Cars'!U64 -> 2 | P31: ='All Cars'!W64 -> 9 | Q31: ='All Cars'!AA64 -> Yes | R31: ='All Cars'!AD64 -> No | S31: ='All Cars'!AC64 -> No | T31: ='All Cars'!AB64 -> Yes | U31: ='All Cars'!M64 -> Gasoline | V31: ='All Cars'!N64 -> 29 | W31: ='All Cars'!AN64 -> Gates Chevrolet South Bend | X31: ='All Cars'!AO64 -> South Bend | Y31: ='All Cars'!AQ64 -> 15.4 | Z31: ='All Cars'!AU64 -> 535.59 | AA31: 2023 Honda CR-V EX | AB31: https://www.carfax.com/vehicle/7FARS4H46PE011892
A32: =RANK(B32,$B$5:$B$40) -> 28 | B32: ='All Cars'!B69 -> 55.8 | C32: ='All Cars'!C69 -> YES | D32: ='All Cars'!D69 -> 2025 | E32: ='All Cars'!E69 -> Honda | F32: ='All Cars'!F69 -> CR-V | G32: ='All Cars'!G69 -> EX | H32: ='All Cars'!H69 -> 30472 | I32: ='All Cars'!I69 -> 41083 | ... K32: ='All Cars'!K69 -> No | L32: ='All Cars'!O69 -> GREAT | M32: ='All Cars'!Q69 -> 0.082 | N32: ='All Cars'!R69 -> GREAT | O32: ='All Cars'!U69 -> 1 | P32: ='All Cars'!W69 -> 5 | Q32: ='All Cars'!AA69 -> Yes | R32: ='All Cars'!AD69 -> No | S32: ='All Cars'!AC69 -> No | T32: ='All Cars'!AB69 -> Yes | U32: ='All Cars'!M69 -> Gasoline | V32: ='All Cars'!N69 -> 28 | W32: ='All Cars'!AN69 -> Zeigler Chrysler Jeep Dodge Ram of Kalamazoo | X32: ='All Cars'!AO69 -> Kalamazoo | Y32: ='All Cars'!AQ69 -> 41.6 | Z32: ='All Cars'!AU69 -> 544.34 | AA32: 2025 Honda CR-V EX | AB32: https://www.carfax.com/vehicle/2HKRS4H49SH430180
A33: =RANK(B33,$B$5:$B$40) -> 29 | B33: ='All Cars'!B77 -> 55.1 | C33: ='All Cars'!C77 -> YES | D33: ='All Cars'!D77 -> 2022 | E33: ='All Cars'!E77 -> Toyota | F33: ='All Cars'!F77 -> 4Runner | G33: ='All Cars'!G77 -> TRD Off Road Premium | H33: ='All Cars'!H77 -> 38104 | I33: ='All Cars'!I77 -> 78455 | ... K33: ='All Cars'!K77 -> No | L33: ='All Cars'!O77 -> GREAT | M33: ='All Cars'!Q77 -> 0 | N33: ='All Cars'!R77 -> GREAT | O33: ='All Cars'!U77 -> 1 | P33: ='All Cars'!W77 -> 17 | Q33: ='All Cars'!AA77 -> Yes | R33: ='All Cars'!AD77 -> No | S33: ='All Cars'!AC77 -> No | T33: ='All Cars'!AB77 -> Yes | U33: ='All Cars'!M77 -> Gasoline | V33: ='All Cars'!N77 -> 17 | W33: ='All Cars'!AN77 -> Gurley Leep Kia | X33: ='All Cars'!AO77 -> Mishawaka | Y33: ='All Cars'!AQ77 -> 11 | Z33: ='All Cars'!AU77 -> 680.67 | AA33: 2022 Toyota 4Runner TRD Off Road Premium | AB33: https://www.carfax.com/vehicle/JTERU5JR4N6047375
A34: =RANK(B34,$B$5:$B$40) -> 30 | B34: ='All Cars'!B78 -> 54.5 | C34: ='All Cars'!C78 -> YES | D34: ='All Cars'!D78 -> 2025 | E34: ='All Cars'!E78 -> Honda | F34: ='All Cars'!F78 -> CR-V | G34: ='All Cars'!G78 -> EX | H34: ='All Cars'!H78 -> 30814 | I34: ='All Cars'!I78 -> 38801 | ... K34: ='All Cars'!K78 -> No | L34: ='All Cars'!O78 -> GREAT | M34: ='All Cars'!Q78 -> 0.076 | N34: ='All Cars'!R78 -> GREAT | O34: ='All Cars'!U78 -> 1 | P34: ='All Cars'!W78 -> 7 | Q34: ='All Cars'!AA78 -> Yes | R34: ='All Cars'!AD78 -> No | S34: ='All Cars'!AC78 -> No | T34: ='All Cars'!AB78 -> Yes | U34: ='All Cars'!M78 -> Gasoline | V34: ='All Cars'!N78 -> 28 | W34: ='All Cars'!AN78 -> Zeigler GMC of Holland | X34: ='All Cars'!AO78 -> Holland | Y34: ='All Cars'!AQ78 -> 74.5 | Z34: ='All Cars'!AU78 -> 550.45 | AA34: 2025 Honda CR-V EX | AB34: https://www.carfax.com/vehicle/2HKRS4H44SH448795
A35: =RANK(B35,$B$5:$B$40) -> 31 | B35: ='All Cars'!B83 -> 54.3 | C35: ='All Cars'!C83 -> YES | D35: ='All Cars'!D83 -> 2022 | E35: ='All Cars'!E83 -> Honda | F35: ='All Cars'!F83 -> CR-V | G35: ='All Cars'!G83 -> EXL | H35: ='All Cars'!H83 -> 28212 | I35: ='All Cars'!I83 -> 54671 | ... K35: ='All Cars'!K83 -> No | L35: ='All Cars'!O83 -> GOOD | M35: ='All Cars'!Q83 -> 0.022 | N35: ='All Cars'!R83 -> GOOD | O35: ='All Cars'!U83 -> 2 | P35: ='All Cars'!W83 -> 17 | Q35: ='All Cars'!AA83 -> Yes | R35: ='All Cars'!AD83 -> Yes | S35: ='All Cars'!AC83 -> Yes | T35: ='All Cars'!AB83 -> Yes | U35: ='All Cars'!M83 -> Hybrid | V35: ='All Cars'!N83 -> 38 | W35: ='All Cars'!AN83 -> Gurley Leep Kia | X35: ='All Cars'!AO83 -> Mishawaka | Y35: ='All Cars'!AQ83 -> 11 | Z35: ='All Cars'!AU83 -> 503.97 | AA35: 2022 Honda CR-V EXL | AB35: https://www.carfax.com/vehicle/5J6RT6H88NL023795
A36: =RANK(B36,$B$5:$B$40) -> 32 | B36: ='All Cars'!B87 -> 53.9 | C36: ='All Cars'!C87 -> YES | D36: ='All Cars'!D87 -> 2024 | E36: ='All Cars'!E87 -> Subaru | F36: ='All Cars'!F87 -> Outback | G36: ='All Cars'!G87 -> Premium | H36: ='All Cars'!H87 -> 25059 | I36: ='All Cars'!I87 -> 33775 | ... K36: ='All Cars'!K87 -> No | L36: ='All Cars'!O87 -> GREAT | M36: ='All Cars'!Q87 -> 0.141 | N36: ='All Cars'!R87 -> GOOD | O36: ='All Cars'!U87 -> 1 | P36: ='All Cars'!W87 -> 4 | Q36: ='All Cars'!AA87 -> Yes | R36: ='All Cars'!AD87 -> Yes | S36: ='All Cars'!AC87 -> No | T36: ='All Cars'!AB87 -> Yes | U36: ='All Cars'!M87 -> Gasoline | V36: ='All Cars'!N87 -> 28 | W36: ='All Cars'!AN87 -> Chevrolet of Merrillville | X36: ='All Cars'!AO87 -> Merrillville | Y36: ='All Cars'!AQ87 -> 71.2 | Z36: ='All Cars'!AU87 -> 447.64 | AA36: 2024 Subaru Outback Premium | AB36: https://www.carfax.com/vehicle/4S4BTAFC6R3136342
A37: =RANK(B37,$B$5:$B$40) -> 33 | B37: ='All Cars'!B93 -> 53.1 | C37: ='All Cars'!C93 -> YES | D37: ='All Cars'!D93 -> 2024 | E37: ='All Cars'!E93 -> Subaru | F37: ='All Cars'!F93 -> Outback | G37: ='All Cars'!G93 -> Onyx Edition | H37: ='All Cars'!H93 -> 29314 | I37: ='All Cars'!I93 -> 37948 | ... K37: ='All Cars'!K93 -> No | L37: ='All Cars'!O93 -> GOOD | M37: ='All Cars'!Q93 -> -0.021 | N37: ='All Cars'!R93 -> GREAT | O37: ='All Cars'!U93 -> 1 | P37: ='All Cars'!W93 -> 11 | Q37: ='All Cars'!AA93 -> Yes | R37: ='All Cars'!AD93 -> Yes | S37: ='All Cars'!AC93 -> Yes | T37: ='All Cars'!AB93 -> Yes | U37: ='All Cars'!M93 -> Gasoline | V37: ='All Cars'!N93 -> 28 | W37: ='All Cars'!AN93 -> Zeigler GMC of Holland | X37: ='All Cars'!AO93 -> Holland | Y37: ='All Cars'!AQ93 -> 74.5 | Z37: ='All Cars'!AU93 -> 523.65 | AA37: 2024 Subaru Outback Onyx Edition | AB37: https://www.carfax.com/vehicle/4S4BTALC5R3189893
A38: =RANK(B38,$B$5:$B$40) -> 34 | B38: ='All Cars'!B100 -> 52.6 | C38: ='All Cars'!C100 -> YES | D38: ='All Cars'!D100 -> 2024 | E38: ='All Cars'!E100 -> Honda | F38: ='All Cars'!F100 -> CR-V | G38: ='All Cars'!G100 -> Sport-L | H38: ='All Cars'!H100 -> 34238 | I38: ='All Cars'!I100 -> 39309 | ... K38: ='All Cars'!K100 -> No | L38: ='All Cars'!O100 -> GOOD | M38: ='All Cars'!Q100 -> -0.064 | N38: ='All Cars'!R100 -> GREAT | O38: ='All Cars'!U100 -> 1 | P38: ='All Cars'!W100 -> 5 | Q38: ='All Cars'!AA100 -> Yes | R38: ='All Cars'!AD100 -> Yes | S38: ='All Cars'!AC100 -> Yes | T38: ='All Cars'!AB100 -> Yes | U38: ='All Cars'!M100 -> Hybrid | V38: ='All Cars'!N100 -> 37 | W38: ='All Cars'!AN100 -> Victory Honda Michigan City | X38: ='All Cars'!AO100 -> MICHIGAN CITY | Y38: ='All Cars'!AQ100 -> 46.9 | Z38: ='All Cars'!AU100 -> 611.61 | AA38: 2024 Honda CR-V Sport-L | AB38: https://www.carfax.com/vehicle/5J6RS6H84RL038433
A39: =RANK(B39,$B$5:$B$40) -> 35 | B39: ='All Cars'!B144 -> 48.7 | C39: ='All Cars'!C144 -> YES | D39: ='All Cars'!D144 -> 2023 | E39: ='All Cars'!E144 -> Subaru | F39: ='All Cars'!F144 -> Outback | G39: ='All Cars'!G144 -> Premium | H39: ='All Cars'!H144 -> 25814 | I39: ='All Cars'!I144 -> 36225 | ... K39: ='All Cars'!K144 -> No | L39: ='All Cars'!O144 -> GOOD | M39: ='All Cars'!Q144 -> 0.052 | N39: ='All Cars'!R144 -> GOOD | O39: ='All Cars'!U144 -> 1 | P39: ='All Cars'!W144 -> 11 | Q39: ='All Cars'!AA144 -> No | R39: ='All Cars'!AD144 -> Yes | S39: ='All Cars'!AC144 -> Yes | T39: ='All Cars'!AB144 -> Yes | U39: ='All Cars'!M144 -> Gasoline | V39: ='All Cars'!N144 -> 28 | W39: ='All Cars'!AN144 -> Zeigler GMC of Holland | X39: ='All Cars'!AO144 -> Holland | Y39: ='All Cars'!AQ144 -> 74.5 | Z39: ='All Cars'!AU144 -> 461.13 | AA39: 2023 Subaru Outback Premium | AB39: https://www.carfax.com/vehicle/4S4BTADC9P3197765
A40: =RANK(B40,$B$5:$B$40) -> 36 | B40: ='All Cars'!B158 -> 47.1 | C40: ='All Cars'!C158 -> YES | D40: ='All Cars'!D158 -> 2024 | E40: ='All Cars'!E158 -> Subaru | F40: ='All Cars'!F158 -> Outback | G40: ='All Cars'!G158 -> Premium | H40: ='All Cars'!H158 -> 26314 | I40: ='All Cars'!I158 -> 39922 | ... K40: ='All Cars'!K158 -> No | L40: ='All Cars'!O158 -> GOOD | M40: ='All Cars'!Q158 -> 0.077 | N40: ='All Cars'!R158 -> GOOD | O40: ='All Cars'!U158 -> 3 | P40: ='All Cars'!W158 -> 11 | Q40: ='All Cars'!AA158 -> Yes | R40: ='All Cars'!AD158 -> Yes | S40: ='All Cars'!AC158 -> Yes | T40: ='All Cars'!AB158 -> Yes | U40: ='All Cars'!M158 -> Gasoline | V40: ='All Cars'!N158 -> 28 | W40: ='All Cars'!AN158 -> Zeigler GMC of Holland | X40: ='All Cars'!AO158 -> Holland | Y40: ='All Cars'!AQ158 -> 74.5 | Z40: ='All Cars'!AU158 -> 470.06 | AA40: 2024 Subaru Outback Premium | AB40: https://www.carfax.com/vehicle/4S4BTAFC1R3240916
A42: "Still Meets" recalculates from the Search Criteria tab. If you tighten a filter, rows that no longer qualify turn red here rather than disappearing - check the All Cars tab for anything new that qualifies.

Sheet Top 10 Compare
A1: Top 10 Head-to-Head
A2: The ten highest-scoring cars from the Shortlist, side by side. Everything here is live-linked to All Cars.
A4: Attribute | B4: #1 2026 Honda CR-V EXL | C4: #2 2025 Honda CR-V EX | D4: #3 2025 Subaru Outback Limited | E4: #4 2024 Honda CR-V Sport | F4: #5 2026 Honda CR-V TrailSport | G4: #6 2023 Honda CR-V Sport Touring | H4: #7 2025 Honda CR-V EX | I4: #8 2025 Honda CR-V Sport-L | J4: #9 2024 Toyota RAV4 Limited Edition | K4: #10 2024 Honda CR-V Sport-L
A5: Score | B5: ='All Cars'!B5 -> 84 | C5: ='All Cars'!B6 -> 72.4 | D5: ='All Cars'!B9 -> 70 | E5: ='All Cars'!B12 -> 69 | F5: ='All Cars'!B13 -> 68.1 | G5: ='All Cars'!B17 -> 66.6 | H5: ='All Cars'!B18 -> 66.5 | I5: ='All Cars'!B19 -> 66.1 | J5: ='All Cars'!B22 -> 64.6 | K5: ='All Cars'!B23 -> 64.5
A6: Year | B6: ='All Cars'!D5 -> 2026 | C6: ='All Cars'!D6 -> 2025 | D6: ='All Cars'!D9 -> 2025 | E6: ='All Cars'!D12 -> 2024 | F6: ='All Cars'!D13 -> 2026 | G6: ='All Cars'!D17 -> 2023 | H6: ='All Cars'!D18 -> 2025 | I6: ='All Cars'!D19 -> 2025 | J6: ='All Cars'!D22 -> 2024 | K6: ='All Cars'!D23 -> 2024
A7: Make | B7: ='All Cars'!E5 -> Honda | C7: ='All Cars'!E6 -> Honda | D7: ='All Cars'!E9 -> Subaru | E7: ='All Cars'!E12 -> Honda | F7: ='All Cars'!E13 -> Honda | G7: ='All Cars'!E17 -> Honda | H7: ='All Cars'!E18 -> Honda | I7: ='All Cars'!E19 -> Honda | J7: ='All Cars'!E22 -> Toyota | K7: ='All Cars'!E23 -> Honda
A8: Model | B8: ='All Cars'!F5 -> CR-V | C8: ='All Cars'!F6 -> CR-V | D8: ='All Cars'!F9 -> Outback | E8: ='All Cars'!F12 -> CR-V | F8: ='All Cars'!F13 -> CR-V | G8: ='All Cars'!F17 -> CR-V | H8: ='All Cars'!F18 -> CR-V | I8: ='All Cars'!F19 -> CR-V | J8: ='All Cars'!F22 -> RAV4 | K8: ='All Cars'!F23 -> CR-V
A9: Trim | B9: ='All Cars'!G5 -> EXL | C9: ='All Cars'!G6 -> EX | D9: ='All Cars'!G9 -> Limited | E9: ='All Cars'!G12 -> Sport | F9: ='All Cars'!G13 -> TrailSport | G9: ='All Cars'!G17 -> Sport Touring | H9: ='All Cars'!G18 -> EX | I9: ='All Cars'!G19 -> Sport-L | J9: ='All Cars'!G22 -> Limited Edition | K9: ='All Cars'!G23 -> Sport-L
A10: Price | B10: ='All Cars'!H5 -> 35415 | C10: ='All Cars'!H6 -> 32809 | D10: ='All Cars'!H9 -> 32609 | E10: ='All Cars'!H12 -> 33809 | F10: ='All Cars'!H13 -> 35913 | G10: ='All Cars'!H17 -> 32864 | H10: ='All Cars'!H18 -> 32809 | I10: ='All Cars'!H19 -> 34798 | J10: ='All Cars'!H22 -> 39338 | K10: ='All Cars'!H23 -> 35190
A11: Mileage | B11: ='All Cars'!I5 -> 12036 | C11: ='All Cars'!I6 -> 15682 | D11: ='All Cars'!I9 -> 31763 | E11: ='All Cars'!I12 -> 25381 | F11: ='All Cars'!I13 -> 9420 | G11: ='All Cars'!I17 -> 34991 | H11: ='All Cars'!I18 -> 23351 | I11: ='All Cars'!I19 -> 20222 | J11: ='All Cars'!I22 -> 17459 | K11: ='All Cars'!I23 -> 23100
A12: Miles/Yr | B12: ='All Cars'!J5 -> 24072 | C12: ='All Cars'!J6 -> 15682 | D12: ='All Cars'!J9 -> 31763 | E12: ='All Cars'!J12 -> 12691 | F12: ='All Cars'!J13 -> 18840 | G12: ='All Cars'!J17 -> 11664 | H12: ='All Cars'!J18 -> 23351 | I12: ='All Cars'!J19 -> 20222 | J12: ='All Cars'!J22 -> 8730 | K12: ='All Cars'!J23 -> 11550
A13: Est. Monthly | B13: ='All Cars'!AU5 -> 632.64 | C13: ='All Cars'!AU6 -> 586.09 | D13: ='All Cars'!AU9 -> 582.51 | E13: ='All Cars'!AU12 -> 603.95 | F13: ='All Cars'!AU13 -> 641.53 | G13: ='All Cars'!AU17 -> 587.07 | H13: ='All Cars'!AU18 -> 586.09 | I13: ='All Cars'!AU19 -> 621.62 | J13: ='All Cars'!AU22 -> 702.72 | K13: ='All Cars'!AU23 -> 628.62
A14: CPO | B14: ='All Cars'!K5 -> Yes | C14: ='All Cars'!K6 -> Yes | D14: ='All Cars'!K9 -> Yes | E14: ='All Cars'!K12 -> Yes | F14: ='All Cars'!K13 -> No | G14: ='All Cars'!K17 -> No | H14: ='All Cars'!K18 -> Yes | I14: ='All Cars'!K19 -> No | J14: ='All Cars'!K22 -> No | K14: ='All Cars'!K23 -> No
A15: Value Badge | B15: ='All Cars'!O5 -> GREAT | C15: ='All Cars'!O6 -> GREAT | D15: ='All Cars'!O9 -> GOOD | E15: ='All Cars'!O12 -> GOOD | F15: ='All Cars'!O13 -> GREAT | G15: ='All Cars'!O17 -> GREAT | H15: ='All Cars'!O18 -> GOOD | I15: ='All Cars'!O19 -> GREAT | J15: ='All Cars'!O22 -> GOOD | K15: ='All Cars'!O23 -> GREAT
A16: Est. Market | B16: ='All Cars'!P5 -> 36351 | C16: ='All Cars'!P6 -> 34961 | D16: ='All Cars'!P9 -> 31035 | E16: ='All Cars'!P12 -> 33153 | F16: ='All Cars'!P13 -> 36532 | G16: ='All Cars'!P17 -> 31351 | H16: ='All Cars'!P18 -> 34432 | I16: ='All Cars'!P19 -> 34648 | J16: ='All Cars'!P22 -> 34583 | K16: ='All Cars'!P23 -> 33311
A17: vs Market | B17: ='All Cars'!Q5 -> 0.026 | C17: ='All Cars'!Q6 -> 0.062 | D17: ='All Cars'!Q9 -> -0.051 | E17: ='All Cars'!Q12 -> -0.02 | F17: ='All Cars'!Q13 -> 0.017 | G17: ='All Cars'!Q17 -> -0.048 | H17: ='All Cars'!Q18 -> 0.047 | I17: ='All Cars'!Q19 -> -0.004 | J17: ='All Cars'!Q22 -> -0.137 | K17: ='All Cars'!Q23 -> -0.056
A18: Reliability | B18: ='All Cars'!R5 -> GREAT | C18: ='All Cars'!R6 -> GREAT | D18: ='All Cars'!R9 -> GREAT | E18: ='All Cars'!R12 -> GREAT | F18: ='All Cars'!R13 -> n/a | G18: ='All Cars'!R17 -> n/a | H18: ='All Cars'!R18 -> GREAT | I18: ='All Cars'!R19 -> n/a | J18: ='All Cars'!R22 -> n/a | K18: ='All Cars'!R23 -> n/a
A19: Repair $/yr | B19: ='All Cars'!S5 -> 190 | C19: ='All Cars'!S6 -> 560 | D19: ='All Cars'!S9 -> 120 | E19: ='All Cars'!S12 -> 600 | F19: ='All Cars'!S13 -> 0 | G19: ='All Cars'!S17 -> 0 | H19: ='All Cars'!S18 -> 840 | I19: ='All Cars'!S19 -> 0 | J19: ='All Cars'!S22 -> 0 | K19: ='All Cars'!S23 -> 0
A20: No Accidents | B20: ='All Cars'!T5 -> Yes | C20: ='All Cars'!T6 -> Yes | D20: ='All Cars'!T9 -> Yes | E20: ='All Cars'!T12 -> Yes | F20: ='All Cars'!T13 -> Yes | G20: ='All Cars'!T17 -> Yes | H20: ='All Cars'!T18 -> Yes | I20: ='All Cars'!T19 -> Yes | J20: ='All Cars'!T22 -> Yes | K20: ='All Cars'!T23 -> Yes
A21: Owners | B21: ='All Cars'!U5 -> 1 | C21: ='All Cars'!U6 -> 1 | D21: ='All Cars'!U9 -> 1 | E21: ='All Cars'!U12 -> 1 | F21: ='All Cars'!U13 -> 1 | G21: ='All Cars'!U17 -> 2 | H21: ='All Cars'!U18 -> 1 | I21: ='All Cars'!U19 -> 1 | J21: ='All Cars'!U22 -> 1 | K21: ='All Cars'!U23 -> 2
A22: Personal Use | B22: ='All Cars'!V5 -> Yes | C22: ='All Cars'!V6 -> Yes | D22: ='All Cars'!V9 -> Yes | E22: ='All Cars'!V12 -> Yes | F22: ='All Cars'!V13 -> Yes | G22: ='All Cars'!V17 -> Yes | H22: ='All Cars'!V18 -> Yes | I22: ='All Cars'!V19 -> Yes | J22: ='All Cars'!V22 -> Yes | K22: ='All Cars'!V23 -> Yes
A23: Service Recs | B23: ='All Cars'!W5 -> 6 | C23: ='All Cars'!W6 -> 4 | D23: ='All Cars'!W9 -> 6 | E23: ='All Cars'!W12 -> 6 | F23: ='All Cars'!W13 -> 3 | G23: ='All Cars'!W17 -> 10 | H23: ='All Cars'!W18 -> 3 | I23: ='All Cars'!W19 -> 7 | J23: ='All Cars'!W22 -> 5 | K23: ='All Cars'!W23 -> 10
A24: Drivetrain | B24: ='All Cars'!L5 -> AWD | C24: ='All Cars'!L6 -> AWD | D24: ='All Cars'!L9 -> AWD | E24: ='All Cars'!L12 -> AWD | F24: ='All Cars'!L13 -> AWD | G24: ='All Cars'!L17 -> AWD | H24: ='All Cars'!L18 -> AWD | I24: ='All Cars'!L19 -> AWD | J24: ='All Cars'!L22 -> AWD | K24: ='All Cars'!L23 -> AWD
A25: Fuel | B25: ='All Cars'!M5 -> Gasoline | C25: ='All Cars'!M6 -> Gasoline | D25: ='All Cars'!M9 -> Gasoline | E25: ='All Cars'!M12 -> Hybrid | F25: ='All Cars'!M13 -> Hybrid | G25: ='All Cars'!M17 -> Hybrid | H25: ='All Cars'!M18 -> Gasoline | I25: ='All Cars'!M19 -> Hybrid | J25: ='All Cars'!M22 -> Gasoline | K25: ='All Cars'!M23 -> Hybrid
A26: MPG | B26: ='All Cars'!N5 -> 29 | C26: ='All Cars'!N6 -> 28 | D26: ='All Cars'!N9 -> 28 | E26: ='All Cars'!N12 -> 37 | F26: ='All Cars'!N13 -> 35 | G26: ='All Cars'!N17 -> 37 | H26: ='All Cars'!N18 -> 28 | I26: ='All Cars'!N19 -> 37 | J26: ='All Cars'!N22 -> 28 | K26: ='All Cars'!N23 -> 37
A27: Heated Seats | B27: ='All Cars'!X5 -> Yes | C27: ='All Cars'!X6 -> Yes | D27: ='All Cars'!X9 -> Yes | E27: ='All Cars'!X12 -> Yes | F27: ='All Cars'!X13 -> Yes | G27: ='All Cars'!X17 -> Yes | H27: ='All Cars'!X18 -> Yes | I27: ='All Cars'!X19 -> Yes | J27: ='All Cars'!X22 -> Yes | K27: ='All Cars'!X23 -> Yes
A28: Heated Steering | B28: ='All Cars'!Z5 -> No | C28: ='All Cars'!Z6 -> No | D28: ='All Cars'!Z9 -> Yes | E28: ='All Cars'!Z12 -> No | F28: ='All Cars'!Z13 -> Yes | G28: ='All Cars'!Z17 -> Yes | H28: ='All Cars'!Z18 -> No | I28: ='All Cars'!Z19 -> No | J28: ='All Cars'!Z22 -> Yes | K28: ='All Cars'!Z23 -> No
A29: Sunroof/Moonroof | B29: ='All Cars'!AA5 -> Yes | C29: ='All Cars'!AA6 -> Yes | D29: ='All Cars'!AA9 -> Yes | E29: ='All Cars'!AA12 -> Yes | F29: ='All Cars'!AA13 -> Yes | G29: ='All Cars'!AA17 -> Yes | H29: ='All Cars'!AA18 -> Yes | I29: ='All Cars'!AA19 -> Yes | J29: ='All Cars'!AA22 -> Yes | K29: ='All Cars'!AA23 -> Yes
A30: Leather | B30: ='All Cars'!AD5 -> Yes | C30: ='All Cars'!AD6 -> No | D30: ='All Cars'!AD9 -> Yes | E30: ='All Cars'!AD12 -> Yes | F30: ='All Cars'!AD13 -> Yes | G30: ='All Cars'!AD17 -> Yes | H30: ='All Cars'!AD18 -> No | I30: ='All Cars'!AD19 -> Yes | J30: ='All Cars'!AD22 -> Yes | K30: ='All Cars'!AD23 -> Yes
A31: Power Liftgate | B31: ='All Cars'!AC5 -> Yes | C31: ='All Cars'!AC6 -> No | D31: ='All Cars'!AC9 -> Yes | E31: ='All Cars'!AC12 -> No | F31: ='All Cars'!AC13 -> Yes | G31: ='All Cars'!AC17 -> Yes | H31: ='All Cars'!AC18 -> No | I31: ='All Cars'!AC19 -> Yes | J31: ='All Cars'!AC22 -> Yes | K31: ='All Cars'!AC23 -> Yes
A32: Blind Spot | B32: ='All Cars'!AB5 -> Yes | C32: ='All Cars'!AB6 -> Yes | D32: ='All Cars'!AB9 -> Yes | E32: ='All Cars'!AB12 -> Yes | F32: ='All Cars'!AB13 -> Yes | G32: ='All Cars'!AB17 -> Yes | H32: ='All Cars'!AB18 -> Yes | I32: ='All Cars'!AB19 -> Yes | J32: ='All Cars'!AB22 -> Yes | K32: ='All Cars'!AB23 -> Yes
A33: Remote Start | B33: ='All Cars'!AE5 -> Yes | C33: ='All Cars'!AE6 -> No | D33: ='All Cars'!AE9 -> No | E33: ='All Cars'!AE12 -> No | F33: ='All Cars'!AE13 -> Yes | G33: ='All Cars'!AE17 -> Yes | H33: ='All Cars'!AE18 -> No | I33: ='All Cars'!AE19 -> Yes | J33: ='All Cars'!AE22 -> No | K33: ='All Cars'!AE23 -> No
A34: Navigation | B34: ='All Cars'!AF5 -> No | C34: ='All Cars'!AF6 -> No | D34: ='All Cars'!AF9 -> Yes | E34: ='All Cars'!AF12 -> No | F34: ='All Cars'!AF13 -> No | G34: ='All Cars'!AF17 -> Yes | H34: ='All Cars'!AF18 -> No | I34: ='All Cars'!AF19 -> No | J34: ='All Cars'!AF22 -> Yes | K34: ='All Cars'!AF23 -> No
A35: Wireless Charging | B35: ='All Cars'!AG5 -> Yes | C35: ='All Cars'!AG6 -> No | D35: ='All Cars'!AG9 -> No | E35: ='All Cars'!AG12 -> No | F35: ='All Cars'!AG13 -> Yes | G35: ='All Cars'!AG17 -> Yes | H35: ='All Cars'!AG18 -> No | I35: ='All Cars'!AG19 -> Yes | J35: ='All Cars'!AG22 -> No | K35: ='All Cars'!AG23 -> Yes
A36: Ext Color | B36: ='All Cars'!AK5 -> Gray | C36: ='All Cars'!AK6 -> Silver | D36: ='All Cars'!AK9 -> Black | E36: ='All Cars'!AK12 -> Blue | F36: ='All Cars'!AK13 -> Gray | G36: ='All Cars'!AK17 -> Blue | H36: ='All Cars'!AK18 -> Silver | I36: ='All Cars'!AK19 -> Silver | J36: ='All Cars'!AK22 -> White | K36: ='All Cars'!AK23 -> Gray
A37: Int Color | B37: ='All Cars'!AL5 -> Black | C37: ='All Cars'!AL6 -> Gray | D37: ='All Cars'!AL9 -> White | E37: ='All Cars'!AL12 -> Black | F37: ='All Cars'!AL13 -> Black | G37: ='All Cars'!AL17 -> Black | H37: ='All Cars'!AL18 -> Gray | I37: ='All Cars'!AL19 -> Black | J37: ='All Cars'!AL22 -> Tan | K37: ='All Cars'!AL23 -> Black
A38: Dealer | B38: ='All Cars'!AN5 -> Gurley Leep Honda | C38: ='All Cars'!AN6 -> Crown Motors Cadillac Buick Honda Mazda | D38: ='All Cars'!AN9 -> Fox Maple Hill | E38: ='All Cars'!AN12 -> Crown Motors Cadillac Buick Honda Mazda | F38: ='All Cars'!AN13 -> Gurley Leep Kia | G38: ='All Cars'!AN17 -> Gurley Leep Hyundai Subaru | H38: ='All Cars'!AN18 -> Crown Motors Cadillac Buick Honda Mazda | I38: ='All Cars'!AN19 -> Jordan Lexus of Mishawaka | J38: ='All Cars'!AN22 -> Gurley Leep Buick GMC Cadillac | K38: ='All Cars'!AN23 -> Zeigler Ford Lincoln Elkhart
A39: City | B39: ='All Cars'!AO5 -> Elkhart | C39: ='All Cars'!AO6 -> Holland | D39: ='All Cars'!AO9 -> Kalamazoo | E39: ='All Cars'!AO12 -> Holland | F39: ='All Cars'!AO13 -> Mishawaka | G39: ='All Cars'!AO17 -> Mishawaka | H39: ='All Cars'!AO18 -> Holland | I39: ='All Cars'!AO19 -> Mishawaka | J39: ='All Cars'!AO22 -> Mishawaka | K39: ='All Cars'!AO23 -> Elkhart
A40: Miles Away | B40: ='All Cars'!AQ5 -> 0.4 | C40: ='All Cars'!AQ6 -> 71 | D40: ='All Cars'!AQ9 -> 42.8 | E40: ='All Cars'!AQ12 -> 71 | F40: ='All Cars'!AQ13 -> 11 | G40: ='All Cars'!AQ17 -> 10.8 | H40: ='All Cars'!AQ18 -> 71 | I40: ='All Cars'!AQ19 -> 11.1 | J40: ='All Cars'!AQ22 -> 10.7 | K40: ='All Cars'!AQ23 -> 3.1
A41: Dealer Rating | B41: ='All Cars'!AR5 -> 4.6 | C41: ='All Cars'!AR6 -> 4.7 | D41: ='All Cars'!AR9 -> 0 | E41: ='All Cars'!AR12 -> 4.7 | F41: ='All Cars'!AR13 -> 4.2 | G41: ='All Cars'!AR17 -> 4.5 | H41: ='All Cars'!AR18 -> 4.7 | I41: ='All Cars'!AR19 -> 4.7 | J41: ='All Cars'!AR22 -> 4.5 | K41: ='All Cars'!AR23 -> 4.6
...

Sheet Model Benchmarks
A1: Model Benchmarks
A2: What each model and year actually goes for in this market. Everything is a live formula over the All Cars tab - it updates if you edit that data.
A4: Make | B4: Model | C4: Year | D4: Cars Listed | E4: Avg Price | F4: Min Price | G4: Max Price | H4: Avg Mileage | I4: Avg Score | J4: CPO Count | K4: Meets-All Count
A5: Honda | B5: CR-V | C5: 2022 | D5: =COUNTIFS('All Cars'!$E$5:$E$266,$A5,'All Cars'!$F$5:$F$266,$B5,'All Cars'!$D$5:$D$266,$C5) -> 5 | E5: =IFERROR(AVERAGEIFS('All Cars'!$H$5:$H$266,'All Cars'!$E$5:$E$266,$A5,'All Cars'!$F$5:$F$266,$B5,'All Cars'!$D$5:$D$266,$C5),"") -> 27888.4 | F5: =IFERROR(_xlfn.MINIFS('All Cars'!$H$5:$H$266,'All Cars'!$E$5:$E$266,$A5,'All Cars'!$F$5:$F$266,$B5,'All Cars'!$D$5:$D$266,$C5),"") -> 26548 | G5: =IFERROR(_xlfn.MAXIFS('All Cars'!$H$5:$H$266,'All Cars'!$E$5:$E$266,$A5,'All Cars'!$F$5:$F$266,$B5,'All Cars'!$D$5:$D$266,$C5),"") -> 28670 | H5: =IFERROR(AVERAGEIFS('All Cars'!$I$5:$I$266,'All Cars'!$E$5:$E$266,$A5,'All Cars'!$F$5:$F$266,$B5,'All Cars'!$D$5:$D$266,$C5),"") -> 54387.2 | I5: =IFERROR(AVERAGEIFS('All Cars'!$B$5:$B$266,'All Cars'!$E$5:$E$266,$A5,'All Cars'!$F$5:$F$266,$B5,'All Cars'!$D$5:$D$266,$C5),"") -> 51.84 | J5: =COUNTIFS('All Cars'!$E$5:$E$266,$A5,'All Cars'!$F$5:$F$266,$B5,'All Cars'!$D$5:$D$266,$C5,'All Cars'!$K$5:$K$266,"Yes") -> 0 | K5: =COUNTIFS('All Cars'!$E$5:$E$266,$A5,'All Cars'!$F$5:$F$266,$B5,'All Cars'!$D$5:$D$266,$C5,'All Cars'!$C$5:$C$266,"YES") -> 2
A6: Honda | B6: CR-V | C6: 2023 | D6: =COUNTIFS('All Cars'!$E$5:$E$266,$A6,'All Cars'!$F$5:$F$266,$B6,'All Cars'!$D$5:$D$266,$C6) -> 15 | E6: =IFERROR(AVERAGEIFS('All Cars'!$H$5:$H$266,'All Cars'!$E$5:$E$266,$A6,'All Cars'!$F$5:$F$266,$B6,'All Cars'!$D$5:$D$266,$C6),"") -> 30764.067 | F6: =IFERROR(_xlfn.MINIFS('All Cars'!$H$5:$H$266,'All Cars'!$E$5:$E$266,$A6,'All Cars'!$F$5:$F$266,$B6,'All Cars'!$D$5:$D$266,$C6),"") -> 26561 | G6: =IFERROR(_xlfn.MAXIFS('All Cars'!$H$5:$H$266,'All Cars'!$E$5:$E$266,$A6,'All Cars'!$F$5:$F$266,$B6,'All Cars'!$D$5:$D$266,$C6),"") -> 33741 | H6: =IFERROR(AVERAGEIFS('All Cars'!$I$5:$I$266,'All Cars'!$E$5:$E$266,$A6,'All Cars'!$F$5:$F$266,$B6,'All Cars'!$D$5:$D$266,$C6),"") -> 50979.133 | I6: =IFERROR(AVERAGEIFS('All Cars'!$B$5:$B$266,'All Cars'!$E$5:$E$266,$A6,'All Cars'!$F$5:$F$266,$B6,'All Cars'!$D$5:$D$266,$C6),"") -> 53.286667 | J6: =COUNTIFS('All Cars'!$E$5:$E$266,$A6,'All Cars'!$F$5:$F$266,$B6,'All Cars'!$D$5:$D$266,$C6,'All Cars'!$K$5:$K$266,"Yes") -> 0 | K6: =COUNTIFS('All Cars'!$E$5:$E$266,$A6,'All Cars'!$F$5:$F$266,$B6,'All Cars'!$D$5:$D$266,$C6,'All Cars'!$C$5:$C$266,"YES") -> 3
A7: Honda | B7: CR-V | C7: 2024 | D7: =COUNTIFS('All Cars'!$E$5:$E$266,$A7,'All Cars'!$F$5:$F$266,$B7,'All Cars'!$D$5:$D$266,$C7) -> 26 | E7: =IFERROR(AVERAGEIFS('All Cars'!$H$5:$H$266,'All Cars'!$E$5:$E$266,$A7,'All Cars'!$F$5:$F$266,$B7,'All Cars'!$D$5:$D$266,$C7),"") -> 32123 | F7: =IFERROR(_xlfn.MINIFS('All Cars'!$H$5:$H$266,'All Cars'!$E$5:$E$266,$A7,'All Cars'!$F$5:$F$266,$B7,'All Cars'!$D$5:$D$266,$C7),"") -> 25990 | G7: =IFERROR(_xlfn.MAXIFS('All Cars'!$H$5:$H$266,'All Cars'!$E$5:$E$266,$A7,'All Cars'!$F$5:$F$266,$B7,'All Cars'!$D$5:$D$266,$C7),"") -> 37990 | H7: =IFERROR(AVERAGEIFS('All Cars'!$I$5:$I$266,'All Cars'!$E$5:$E$266,$A7,'All Cars'!$F$5:$F$266,$B7,'All Cars'!$D$5:$D$266,$C7),"") -> 39449.269 | I7: =IFERROR(AVERAGEIFS('All Cars'!$B$5:$B$266,'All Cars'!$E$5:$E$266,$A7,'All Cars'!$F$5:$F$266,$B7,'All Cars'!$D$5:$D$266,$C7),"") -> 55.761538 | J7: =COUNTIFS('All Cars'!$E$5:$E$266,$A7,'All Cars'!$F$5:$F$266,$B7,'All Cars'!$D$5:$D$266,$C7,'All Cars'!$K$5:$K$266,"Yes") -> 3 | K7: =COUNTIFS('All Cars'!$E$5:$E$266,$A7,'All Cars'!$F$5:$F$266,$B7,'All Cars'!$D$5:$D$266,$C7,'All Cars'!$C$5:$C$266,"YES") -> 6
A8: Honda | B8: CR-V | C8: 2025 | D8: =COUNTIFS('All Cars'!$E$5:$E$266,$A8,'All Cars'!$F$5:$F$266,$B8,'All Cars'!$D$5:$D$266,$C8) -> 18 | E8: =IFERROR(AVERAGEIFS('All Cars'!$H$5:$H$266,'All Cars'!$E$5:$E$266,$A8,'All Cars'!$F$5:$F$266,$B8,'All Cars'!$D$5:$D$266,$C8),"") -> 33886.889 | F8: =IFERROR(_xlfn.MINIFS('All Cars'!$H$5:$H$266,'All Cars'!$E$5:$E$266,$A8,'All Cars'!$F$5:$F$266,$B8,'All Cars'!$D$5:$D$266,$C8),"") -> 29024 | G8: =IFERROR(_xlfn.MAXIFS('All Cars'!$H$5:$H$266,'All Cars'!$E$5:$E$266,$A8,'All Cars'!$F$5:$F$266,$B8,'All Cars'!$D$5:$D$266,$C8),"") -> 38238 | H8: =IFERROR(AVERAGEIFS('All Cars'!$I$5:$I$266,'All Cars'!$E$5:$E$266,$A8,'All Cars'!$F$5:$F$266,$B8,'All Cars'!$D$5:$D$266,$C8),"") -> 30774.333 | I8: =IFERROR(AVERAGEIFS('All Cars'!$B$5:$B$266,'All Cars'!$E$5:$E$266,$A8,'All Cars'!$F$5:$F$266,$B8,'All Cars'!$D$5:$D$266,$C8),"") -> 56.705556 | J8: =COUNTIFS('All Cars'!$E$5:$E$266,$A8,'All Cars'!$F$5:$F$266,$B8,'All Cars'!$D$5:$D$266,$C8,'All Cars'!$K$5:$K$266,"Yes") -> 2 | K8: =COUNTIFS('All Cars'!$E$5:$E$266,$A8,'All Cars'!$F$5:$F$266,$B8,'All Cars'!$D$5:$D$266,$C8,'All Cars'!$C$5:$C$266,"YES") -> 8
A9: Honda | B9: CR-V | C9: 2026 | D9: =COUNTIFS('All Cars'!$E$5:$E$266,$A9,'All Cars'!$F$5:$F$266,$B9,'All Cars'!$D$5:$D$266,$C9) -> 4 | E9: =IFERROR(AVERAGEIFS('All Cars'!$H$5:$H$266,'All Cars'!$E$5:$E$266,$A9,'All Cars'!$F$5:$F$266,$B9,'All Cars'!$D$5:$D$266,$C9),"") -> 35994.75 | F9: =IFERROR(_xlfn.MINIFS('All Cars'!$H$5:$H$266,'All Cars'!$E$5:$E$266,$A9,'All Cars'!$F$5:$F$266,$B9,'All Cars'!$D$5:$D$266,$C9),"") -> 34661 | G9: =IFERROR(_xlfn.MAXIFS('All Cars'!$H$5:$H$266,'All Cars'!$E$5:$E$266,$A9,'All Cars'!$F$5:$F$266,$B9,'All Cars'!$D$5:$D$266,$C9),"") -> 37990 | H9: =IFERROR(AVERAGEIFS('All Cars'!$I$5:$I$266,'All Cars'!$E$5:$E$266,$A9,'All Cars'!$F$5:$F$266,$B9,'All Cars'!$D$5:$D$266,$C9),"") -> 14458.5 | I9: =IFERROR(AVERAGEIFS('All Cars'!$B$5:$B$266,'All Cars'!$E$5:$E$266,$A9,'All Cars'!$F$5:$F$266,$B9,'All Cars'!$D$5:$D$266,$C9),"") -> 65.375 | J9: =COUNTIFS('All Cars'!$E$5:$E$266,$A9,'All Cars'!$F$5:$F$266,$B9,'All Cars'!$D$5:$D$266,$C9,'All Cars'!$K$5:$K$266,"Yes") -> 1 | K9: =COUNTIFS('All Cars'!$E$5:$E$266,$A9,'All Cars'!$F$5:$F$266,$B9,'All Cars'!$D$5:$D$266,$C9,'All Cars'!$C$5:$C$266,"YES") -> 2
